<?xml version='1.0'?>
<sdf version='1.5'>
  <model name='Test UAV'>

    <include>
      <uri>model://iris</uri>
    </include>

    <include>
      <uri>model://fpv_cam</uri>
      <pose>0 0 0 0 1.57 1.57</pose>
    </include>

    <joint name="fpv_cam_joint" type="fixed">
      <child>fpv_cam::link</child>
      <parent>iris::base_link</parent>
      <axis>
        <xyz>0 0 1</xyz>
        <limit>
          <upper>0</upper>
          <lower>0</lower>
        </limit>
      </axis>
    </joint>


    <!--定义连杆-->
    <link name="Link0">
	    <pose>0.195 0 0.05 0 -1.57 0</pose>
        <inertial>
          <mass>0.001</mass>
          <inertia>
            <ixx>1.3347395e-04</ixx>
            <ixy>0</ixy>
            <ixz>0</ixz>
            <iyy>1.3347395e-04</iyy>
            <iyz>0</iyz>
            <izz>2.8125e-06</izz>
          </inertia>
        </inertial>
      <collision name  = 'collision0'>
        <geometry>
		      <cylinder>
			      <radius>0.0075</radius>
            <length>0.39</length>
          </cylinder>
        </geometry>
        <max_contacts>10</max_contacts>
        <surface>
          <contact>
            <ode/>
          </contact>
          <bounce/>
          <friction>
            <ode/>
          </friction>
        </surface>
      </collision>
      <visual name='visual0'>
        <geometry>
		      <cylinder>
		      	<radius>0.0075</radius>
            <length>0.39</length>
          </cylinder>
        </geometry>
        <material>
          <script>
            <name>Gazebo/Indigo</name>
          </script>
        </material>
      </visual>
    </link>

    <joint name="Link0_joint" type="fixed">
      <child>Link0</child>
      <parent>iris::base_link</parent>
      <axis>
        <xyz>0 0 0</xyz>
        <limit>
          <upper>0</upper>
          <lower>0</lower>
        </limit>
      </axis>
    </joint>


    <link name="sensor_link">
      <pose>0.395 0 0.05 0 -1.57 0</pose>
      <inertial>
        <mass>0.01</mass>
        <inertia>
    	  <ixx>7.1441e-05</ixx>
    	  <ixy>0.0</ixy>
    	  <ixz>0.0</ixz>
    	  <iyy>7.146e-05</iyy>
    	  <iyz>0.0</iyz>
  	    <izz>1.3366e-05</izz>
        </inertia>
      </inertial>
      <collision name  = 'force_sensor_collision'>
        <geometry>
	  <cylinder>
	    <radius>0.0075</radius>
            <length>0.01</length>
          </cylinder>
        </geometry>
      </collision>
      <visual name='force_sensor_visual'>
        <geometry>
          <cylinder>
            <radius>0.0075</radius>
            <length>0.001</length>
          </cylinder>
        </geometry>
        <material>
          <script>
            <name>Gazebo/Red</name>
          </script>
        </material>
      </visual>
    </link>
            
    <joint name="force_sensor_joint" type="revolute">
      <child>sensor_link</child>
      <parent>Link0</parent>
      <axis>
        <limit>
          <lower>-1.57079</lower>
          <upper>1.57079</upper>
        </limit>
        <dynamics>
          <damping>0.000000</damping>
          <friction>0.000000</friction>
        </dynamics>
        <xyz>0.000000 0.000000 0.000000</xyz>
      </axis>
      <sensor name="force_torque" type="force_torque">
      </sensor>
    </joint>

    <plugin name="ft_sensor" filename="libgazebo_ros_ft_sensor.so">
      <updateRate>30.0</updateRate>
      <topicName>iris/force_sensor/ft_sensor_topic</topicName>
      <jointName>force_sensor_joint</jointName>
    </plugin>


    

    
    <!-- <link name='chassis'>
      <pose frame=''>cc
      <static>true</static>
      <self_collide>0</self_collide>
      <kinematic>0</kinematic>
      <gravity>1</gravity>
      <inertial>
        <mass>10</mass>
        <pose frame=''>1.0 0 1.5 0 0 -1.57</pose>
        <inertia>
          <ixx>1</ixx>
          <ixy>0</ixy>
          <ixz>0</ixz>
          <iyy>1</iyy>
          <iyz>0</iyz>
          <izz>1</izz>
        </inertia>
      </inertial>
      <visual name='visual'>
        <geometry>
          <mesh>
            <uri>model://brick_box_3x1x3/meshes/simple_box.dae</uri>
            <scale>3 1 3</scale>
          </mesh>
        </geometry>
        <material>
          <script>
            <uri>model://brick_box_3x1x3/materials/scripts</uri>
            <uri>model://brick_box_3x1x3/materials/textures</uri>
            <name>BrickBox/Diffuse</name>
          </script>
          <ambient>1 1 1 1</ambient>
          <diffuse>1 1 1 1</diffuse>
          <specular>0 0 0 1</specular>
          <emissive>0 0 0 1</emissive>
          <shader type='vertex'>
            <normal_map>__default__</normal_map>
          </shader>
        </material>
        <pose frame=''>1.0 0 1.5 0 0 -1.57</pose>
        <cast_shadows>1</cast_shadows>
        <transparency>0</transparency>
      </visual>
      <collision name='collision'>
        <laser_retro>0</laser_retro>
        <max_contacts>10</max_contacts>
        <pose frame=''>1.0 0 1.5 0 0 -1.57</pose>
        <geometry>
          <box>
            <size>3 1 3</size>
          </box>
        </geometry>
        <surface>
          <friction>
            <ode>
              <mu>1</mu>
              <mu2>1</mu2>
              <fdir1>0 0 0</fdir1>
              <slip1>0</slip1>
              <slip2>0</slip2>
            </ode>
            <torsional>
              <coefficient>1</coefficient>
              <patch_radius>0</patch_radius>
              <surface_radius>0</surface_radius>
              <use_patch_radius>1</use_patch_radius>
              <ode>
                <slip>0</slip>
              </ode>
            </torsional>
          </friction>
          <bounce>
            <restitution_coefficient>0</restitution_coefficient>
            <threshold>1e+06</threshold>
          </bounce>
          <contact>
            <collide_without_contact>0</collide_without_contact>
            <collide_without_contact_bitmask>1</collide_without_contact_bitmask>
            <collide_bitmask>1</collide_bitmask>
            <ode>
              <soft_cfm>0</soft_cfm>
              <soft_erp>0.2</soft_erp>
              <kp>1e+13</kp>
              <kd>1</kd>
              <max_vel>0.01</max_vel>
              <min_depth>0</min_depth>
            </ode>
            <bullet>
              <split_impulse>1</split_impulse>
              <split_impulse_penetration_threshold>-0.01</split_impulse_penetration_threshold>
              <soft_cfm>0</soft_cfm>
              <soft_erp>0.2</soft_erp>
              <kp>1e+13</kp>
              <kd>1</kd>
            </bullet>
          </contact>
        </surface>
      </collision>
    </link>
    <static>1</static>
    <allow_auto_disable>1</allow_auto_disable> -->



  </model>
</sdf>
