<sdf version='1.7'>
  <world name='default'>
    <light name='sun' type='directional'>
      <cast_shadows>1</cast_shadows>
      <pose>0 0 10 0 -0 0</pose>
      <diffuse>0.8 0.8 0.8 1</diffuse>
      <specular>0.2 0.2 0.2 1</specular>
      <attenuation>
        <range>1000</range>
        <constant>0.9</constant>
        <linear>0.01</linear>
        <quadratic>0.001</quadratic>
      </attenuation>
      <direction>-0.5 0.1 -0.9</direction>
      <spot>
        <inner_angle>0</inner_angle>
        <outer_angle>0</outer_angle>
        <falloff>0</falloff>
      </spot>
    </light>
    <model name='ground_plane'>
      <static>1</static>
      <link name='link'>
        <collision name='collision'>
          <geometry>
            <plane>
              <normal>0 0 1</normal>
              <size>100 100</size>
            </plane>
          </geometry>
          <surface>
            <contact>
              <collide_bitmask>65535</collide_bitmask>
              <ode/>
            </contact>
            <friction>
              <ode>
                <mu>100</mu>
                <mu2>50</mu2>
              </ode>
              <torsional>
                <ode/>
              </torsional>
            </friction>
            <bounce/>
          </surface>
          <max_contacts>10</max_contacts>
        </collision>
        <visual name='visual'>
          <cast_shadows>0</cast_shadows>
          <geometry>
            <plane>
              <normal>0 0 1</normal>
              <size>100 100</size>
            </plane>
          </geometry>
          <material>
            <script>
              <uri>file://media/materials/scripts/gazebo.material</uri>
              <name>Gazebo/Grey</name>
            </script>
          </material>
        </visual>
        <self_collide>0</self_collide>
        <enable_wind>0</enable_wind>
        <kinematic>0</kinematic>
      </link>
    </model>
    <model name='asphalt_plane'>
      <static>1</static>
      <link name='link'>
        <collision name='collision'>
          <geometry>
            <box>
              <size>200 200 0.1</size>
            </box>
          </geometry>
          <max_contacts>10</max_contacts>
          <surface>
            <contact>
              <ode/>
            </contact>
            <bounce/>
            <friction>
              <torsional>
                <ode/>
              </torsional>
              <ode/>
            </friction>
          </surface>
        </collision>
        <visual name='visual'>
          <cast_shadows>0</cast_shadows>
          <geometry>
            <box>
              <size>200 200 0.1</size>
            </box>
          </geometry>
          <material>
            <script>
              <uri>model://asphalt_plane/materials/scripts</uri>
              <uri>model://asphalt_plane/materials/textures</uri>
              <name>vrc/asphalt</name>
            </script>
          </material>
        </visual>
        <self_collide>0</self_collide>
        <enable_wind>0</enable_wind>
        <kinematic>0</kinematic>
      </link>
    </model>
    <light name='user_point_light_0' type='point'>
      <pose>-0.191859 0.550154 7.02258 0 -0 0</pose>
      <diffuse>0.5 0.5 0.5 1</diffuse>
      <specular>0.1 0.1 0.1 1</specular>
      <attenuation>
        <range>20</range>
        <constant>0.5</constant>
        <linear>0.01</linear>
        <quadratic>0.001</quadratic>
      </attenuation>
      <cast_shadows>0</cast_shadows>
      <direction>0 0 -1</direction>
      <spot>
        <inner_angle>0</inner_angle>
        <outer_angle>0</outer_angle>
        <falloff>0</falloff>
      </spot>
    </light>
    <physics name='default_physics' default='0' type='ode'>
      <ode>
        <solver>
          <type>quick</type>
          <iters>20</iters>
          <sor>1</sor>
          <use_dynamic_moi_rescaling>0</use_dynamic_moi_rescaling>
        </solver>
        <constraints>
          <cfm>0</cfm>
          <erp>0.2</erp>
          <contact_max_correcting_vel>100</contact_max_correcting_vel>
          <contact_surface_layer>0.001</contact_surface_layer>
        </constraints>
      </ode>
      <max_step_size>0.004</max_step_size>
      <real_time_factor>1</real_time_factor>
      <real_time_update_rate>250</real_time_update_rate>
    </physics>
    <gravity>0 0 -9.8066</gravity>
    <magnetic_field>6e-06 2.3e-05 -4.2e-05</magnetic_field>
    <atmosphere type='adiabatic'/>
    <scene>
      <ambient>0.4 0.4 0.4 1</ambient>
      <background>0.7 0.7 0.7 1</background>
      <shadows>1</shadows>
    </scene>
    <wind/>
    <spherical_coordinates>
      <surface_model>EARTH_WGS84</surface_model>
      <latitude_deg>0</latitude_deg>
      <longitude_deg>0</longitude_deg>
      <elevation>0</elevation>
      <heading_deg>0</heading_deg>
    </spherical_coordinates>
    <model name='skyvortex'>
      <link name='base_link'>
        <pose>0 0 0 0 -0 0</pose>
        <inertial>
          <pose>0 -0.002137 0.004638 0 -0 0</pose>
          <mass>4.1077</mass>
          <inertia>
            <ixx>0.156038</ixx>
            <ixy>0</ixy>
            <ixz>0</ixz>
            <iyy>0.15676</iyy>
            <iyz>0</iyz>
            <izz>0.290817</izz>
          </inertia>
        </inertial>
        <collision name='collision_youqian'>
          <pose relative_to='base_link'>0.030677 -0.25355 -0.17398 -0.174537 -0.354014 -0.445166</pose>
          <geometry>
            <cylinder>
              <radius>0.0301498</radius>
              <length>0.350893</length>
            </cylinder>
          </geometry>
          <surface>
            <friction>
              <ode>
                <mu>1</mu>
                <mu2>1</mu2>
              </ode>
              <torsional>
                <ode/>
              </torsional>
            </friction>
            <contact>
              <ode>
                <kp>1e+08</kp>
                <kd>1</kd>
                <max_vel>0.01</max_vel>
                <min_depth>0.001</min_depth>
              </ode>
            </contact>
            <bounce/>
          </surface>
          <max_contacts>10</max_contacts>
        </collision>
        <collision name='collision_youhou'>
          <pose relative_to='base_link'>-0.23492 -0.10021 -0.17398 0.387586 -0.032078 1.49235</pose>
          <geometry>
            <cylinder>
              <radius>0.0301498</radius>
              <length>0.350893</length>
            </cylinder>
          </geometry>
          <surface>
            <friction>
              <ode>
                <mu>1</mu>
                <mu2>1</mu2>
              </ode>
              <torsional>
                <ode/>
              </torsional>
            </friction>
            <contact>
              <ode>
                <kp>1e+08</kp>
                <kd>1</kd>
                <max_vel>0.01</max_vel>
                <min_depth>0.001</min_depth>
              </ode>
            </contact>
            <bounce/>
          </surface>
          <max_contacts>10</max_contacts>
        </collision>
        <collision name='collision_zuoqian'>
          <pose relative_to='base_link'>0.23492 0.10021 -0.17398 -0.387586 0.032078 1.49235</pose>
          <geometry>
            <cylinder>
              <radius>0.0301498</radius>
              <length>0.350893</length>
            </cylinder>
          </geometry>
          <surface>
            <friction>
              <ode>
                <mu>1</mu>
                <mu2>1</mu2>
              </ode>
              <torsional>
                <ode/>
              </torsional>
            </friction>
            <contact>
              <ode>
                <kp>1e+08</kp>
                <kd>1</kd>
                <max_vel>0.01</max_vel>
                <min_depth>0.001</min_depth>
              </ode>
            </contact>
            <bounce/>
          </surface>
          <max_contacts>10</max_contacts>
        </collision>
        <collision name='collision_zuohou'>
          <pose relative_to='base_link'>-0.030677 0.25355 -0.17398 0.174537 0.354014 -0.445166</pose>
          <geometry>
            <cylinder>
              <radius>0.0301498</radius>
              <length>0.350893</length>
            </cylinder>
          </geometry>
          <surface>
            <friction>
              <ode>
                <mu>1</mu>
                <mu2>1</mu2>
              </ode>
              <torsional>
                <ode/>
              </torsional>
            </friction>
            <contact>
              <ode>
                <kp>1e+08</kp>
                <kd>1</kd>
                <max_vel>0.01</max_vel>
                <min_depth>0.001</min_depth>
              </ode>
            </contact>
            <bounce/>
          </surface>
          <max_contacts>10</max_contacts>
        </collision>
        <gravity>1</gravity>
        <velocity_decay/>
        <self_collide>0</self_collide>
        <enable_wind>0</enable_wind>
        <kinematic>0</kinematic>
      </link>
      <joint name='operator_1_joint' type='revolute'>
        <pose relative_to='base_link'>0.000871 0.000172 0.028455 0 -0 0</pose>
        <parent>base_link</parent>
        <child>operator_1_Link</child>
        <axis>
          <xyz>-0.01699 -0.99986 0</xyz>
          <limit>
            <lower>-1e+16</lower>
            <upper>1e+16</upper>
            <effort>100</effort>
            <velocity>-1</velocity>
          </limit>
          <dynamics>
            <damping>1</damping>
            <spring_reference>0</spring_reference>
            <spring_stiffness>0</spring_stiffness>
          </dynamics>
          <use_parent_model_frame>1</use_parent_model_frame>
        </axis>
        <physics>
          <ode>
            <implicit_spring_damper>1</implicit_spring_damper>
            <limit>
              <cfm>0</cfm>
              <erp>0.2</erp>
            </limit>
          </ode>
        </physics>
      </joint>
      <link name='operator_1_Link'>
        <pose relative_to='operator_1_joint'>0 0 0 0 -0 0</pose>
        <inertial>
          <pose>-0.039322 0.00272 -0.023277 0 -0 0</pose>
          <mass>0.01</mass>
          <inertia>
            <ixx>1</ixx>
            <ixy>0</ixy>
            <ixz>0</ixz>
            <iyy>1</iyy>
            <iyz>0</iyz>
            <izz>1</izz>
          </inertia>
        </inertial>
        <gravity>1</gravity>
        <velocity_decay/>
        <self_collide>0</self_collide>
        <enable_wind>0</enable_wind>
        <kinematic>0</kinematic>
      </link>
      <joint name='connect_joint' type='prismatic'>
        <pose relative_to='operator_1_Link'>0.515159 -0.008754 0.29747 2.0944 0 -1.58779</pose>
        <parent>operator_1_Link</parent>
        <child>connect_Link</child>
        <axis>
          <xyz>0 0 1</xyz>
          <limit>
            <lower>0</lower>
            <upper>0</upper>
            <effort>0</effort>
            <velocity>0</velocity>
          </limit>
          <dynamics>
            <spring_reference>0</spring_reference>
            <spring_stiffness>0</spring_stiffness>
          </dynamics>
        </axis>
      </joint>
      <link name='connect_Link'>
        <pose relative_to='connect_joint'>0 0 0 0 -0 0</pose>
        <inertial>
          <pose>0.00023 -0.008308 -0.339949 0 -0 0</pose>
          <mass>0.0004535</mass>
          <inertia>
            <ixx>0.00261433</ixx>
            <ixy>-4.53611e-07</ixy>
            <ixz>-9.17011e-06</ixz>
            <iyy>0.00255743</iyy>
            <iyz>-9.3336e-05</iyz>
            <izz>0.000227535</izz>
          </inertia>
        </inertial>
        <collision name='connect_Link_collision'>
          <pose>0 0 0 0 -0 0</pose>
          <geometry>
            <mesh>
              <scale>1 1 1</scale>
              <uri>model://end_effector/meshes/connect_Link.STL</uri>
            </mesh>
          </geometry>
          <max_contacts>10</max_contacts>
          <surface>
            <contact>
              <ode/>
            </contact>
            <bounce/>
            <friction>
              <torsional>
                <ode/>
              </torsional>
              <ode/>
            </friction>
          </surface>
        </collision>
        <collision name='connect_Link_fixed_joint_lump__move_base_Link_collision_1'>
          <pose>0 0 -0.4115 0 -0 0</pose>
          <geometry>
            <mesh>
              <scale>1 1 1</scale>
              <uri>model://end_effector/meshes/move_base_Link.STL</uri>
            </mesh>
          </geometry>
          <max_contacts>10</max_contacts>
          <surface>
            <contact>
              <ode/>
            </contact>
            <bounce/>
            <friction>
              <torsional>
                <ode/>
              </torsional>
              <ode/>
            </friction>
          </surface>
        </collision>
        <self_collide>0</self_collide>
        <enable_wind>0</enable_wind>
        <kinematic>0</kinematic>
      </link>
      <joint name='wheel1_joint' type='revolute'>
        <pose relative_to='connect_Link'>0 0.085482 -0.4 0 -0 0</pose>
        <parent>connect_Link</parent>
        <child>wheel1_Link</child>
        <axis>
          <xyz>0 1 0</xyz>
          <limit>
            <lower>-1e+16</lower>
            <upper>1e+16</upper>
          </limit>
          <dynamics>
            <spring_reference>0</spring_reference>
            <spring_stiffness>0</spring_stiffness>
          </dynamics>
        </axis>
      </joint>
      <link name='wheel1_Link'>
        <pose relative_to='wheel1_joint'>0 0 0 0 -0 0</pose>
        <inertial>
          <pose>-1e-06 -0.002478 -4.3e-05 0 -0 0</pose>
          <mass>0.00041284</mass>
          <inertia>
            <ixx>2.4836e-06</ixx>
            <ixy>1.6072e-10</ixy>
            <ixz>-1.849e-10</ixz>
            <iyy>4.093e-06</iyy>
            <iyz>-1.5731e-10</iyz>
            <izz>2.4836e-06</izz>
          </inertia>
        </inertial>
        <collision name='wheel1_Link_collision'>
          <pose>0 0 0 0 -0 0</pose>
          <geometry>
            <mesh>
              <scale>1 1 1</scale>
              <uri>model://end_effector/meshes/wheel1_Link.STL</uri>
            </mesh>
          </geometry>
          <max_contacts>10</max_contacts>
          <surface>
            <contact>
              <ode/>
            </contact>
            <bounce/>
            <friction>
              <torsional>
                <ode/>
              </torsional>
              <ode/>
            </friction>
          </surface>
        </collision>
        <self_collide>0</self_collide>
        <enable_wind>0</enable_wind>
        <kinematic>0</kinematic>
      </link>
      <joint name='wheel2_joint' type='revolute'>
        <pose relative_to='connect_Link'>0.07403 -0.042741 -0.4 0 0 -2.0944</pose>
        <parent>connect_Link</parent>
        <child>wheel2_Link</child>
        <axis>
          <xyz>0 1 0</xyz>
          <limit>
            <lower>-1e+16</lower>
            <upper>1e+16</upper>
          </limit>
          <dynamics>
            <spring_reference>0</spring_reference>
            <spring_stiffness>0</spring_stiffness>
          </dynamics>
        </axis>
      </joint>
      <link name='wheel2_Link'>
        <pose relative_to='wheel2_joint'>0 0 0 0 -0 0</pose>
        <inertial>
          <pose>-1e-06 -0.002344 2e-06 0 -0 0</pose>
          <mass>0.00041284</mass>
          <inertia>
            <ixx>2.4817e-06</ixx>
            <ixy>1.6072e-10</ixy>
            <ixz>-1.8492e-10</ixz>
            <iyy>4.0926e-06</iyy>
            <iyz>-1.5732e-10</iyz>
            <izz>2.4817e-06</izz>
          </inertia>
        </inertial>
        <collision name='wheel2_Link_collision'>
          <pose>0 0 0 0 -0 0</pose>
          <geometry>
            <mesh>
              <scale>1 1 1</scale>
              <uri>model://end_effector/meshes/wheel2_Link.STL</uri>
            </mesh>
          </geometry>
          <max_contacts>10</max_contacts>
          <surface>
            <contact>
              <ode/>
            </contact>
            <bounce/>
            <friction>
              <torsional>
                <ode/>
              </torsional>
              <ode/>
            </friction>
          </surface>
        </collision>
        <self_collide>0</self_collide>
        <enable_wind>0</enable_wind>
        <kinematic>0</kinematic>
      </link>
      <joint name='wheel3_joint' type='revolute'>
        <pose relative_to='connect_Link'>-0.07403 -0.042741 -0.4 0 -0 2.0944</pose>
        <parent>connect_Link</parent>
        <child>wheel3_Link</child>
        <axis>
          <xyz>0 1 0</xyz>
          <limit>
            <lower>-1e+16</lower>
            <upper>1e+16</upper>
          </limit>
          <dynamics>
            <spring_reference>0</spring_reference>
            <spring_stiffness>0</spring_stiffness>
          </dynamics>
        </axis>
      </joint>
      <link name='wheel3_Link'>
        <pose relative_to='wheel3_joint'>0 0 0 0 -0 0</pose>
        <inertial>
          <pose>-1e-06 -0.002344 2e-06 0 -0 0</pose>
          <mass>0.00041284</mass>
          <inertia>
            <ixx>2.4817e-06</ixx>
            <ixy>1.6071e-10</ixy>
            <ixz>-1.8491e-10</ixz>
            <iyy>4.0926e-06</iyy>
            <iyz>-1.5732e-10</iyz>
            <izz>2.4817e-06</izz>
          </inertia>
        </inertial>
        <collision name='wheel3_Link_collision'>
          <pose>0 0 0 0 -0 0</pose>
          <geometry>
            <mesh>
              <scale>1 1 1</scale>
              <uri>model://end_effector/meshes/wheel3_Link.STL</uri>
            </mesh>
          </geometry>
          <max_contacts>10</max_contacts>
          <surface>
            <contact>
              <ode/>
            </contact>
            <bounce/>
            <friction>
              <torsional>
                <ode/>
              </torsional>
              <ode/>
            </friction>
          </surface>
        </collision>
        <self_collide>0</self_collide>
        <enable_wind>0</enable_wind>
        <kinematic>0</kinematic>
      </link>
      <joint name='force_sensor_joint' type='fixed'>
        <pose relative_to='operator_1_Link'>0.832 -0.013 0.482 0 1.05 0</pose>
        <child>force_sensor</child>
        <parent>operator_1_Link</parent>
        <axis>
          <xyz>1 0 0</xyz>
          <limit>
            <lower>0</lower>
            <upper>0</upper>
            <effort>0</effort>
            <velocity>0</velocity>
          </limit>
          <dynamics>
            <spring_reference>0</spring_reference>
            <spring_stiffness>0</spring_stiffness>
          </dynamics>
          <use_parent_model_frame>1</use_parent_model_frame>
        </axis>
        <sensor name='force_torque' type='force_torque'>
          <update_rate>30</update_rate>
          <visualize>1</visualize>
          <force_torque/>
        </sensor>
      </joint>
      <link name='force_sensor'>
        <pose relative_to='force_sensor_joint'>0 0 0 0 -0 0</pose>
        <inertial>
          <pose>0 0 0 0 -0 0</pose>
          <mass>0.001</mass>
          <inertia>
            <ixx>1e-05</ixx>
            <ixy>0</ixy>
            <ixz>0</ixz>
            <iyy>1e-05</iyy>
            <iyz>0</iyz>
            <izz>1e-05</izz>
          </inertia>
        </inertial>
        <collision name='force_sensor_collision'>
          <pose relative_to='force_sensor_joint'>0 0 0 0 -0 0</pose>
          <geometry>
            <box>
              <size>0.03 0.03 0.001</size>
            </box>
          </geometry>
          <max_contacts>10</max_contacts>
          <surface>
            <contact>
              <ode/>
            </contact>
            <bounce/>
            <friction>
              <torsional>
                <ode/>
              </torsional>
              <ode/>
            </friction>
          </surface>
        </collision>
        <gravity>1</gravity>
        <velocity_decay/>
        <self_collide>0</self_collide>
        <enable_wind>0</enable_wind>
        <kinematic>0</kinematic>
      </link>
      <joint name='rotor_0_joint' type='revolute'>
        <pose relative_to='base_link'>0.44207 0.2778 0.033856 0 -0 0</pose>
        <parent>base_link</parent>
        <child>rotor_0</child>
        <axis>
          <xyz>-0.25 0.43301 0.86603</xyz>
          <limit>
            <lower>-1e+16</lower>
            <upper>1e+16</upper>
            <effort>10</effort>
            <velocity>-1</velocity>
          </limit>
          <dynamics>
            <damping>0.005</damping>
            <spring_reference>0</spring_reference>
            <spring_stiffness>0</spring_stiffness>
          </dynamics>
          <use_parent_model_frame>1</use_parent_model_frame>
        </axis>
        <physics>
          <ode>
            <implicit_spring_damper>1</implicit_spring_damper>
            <limit>
              <cfm>0</cfm>
              <erp>0.2</erp>
            </limit>
          </ode>
        </physics>
      </joint>
      <link name='rotor_0'>
        <pose relative_to='rotor_0_joint'>0 0 0 0 -0 0</pose>
        <inertial>
          <pose>0.001269 0.000215 -0.000505 0 -0 0</pose>
          <mass>0.015914</mass>
          <inertia>
            <ixx>0.00019374</ixx>
            <ixy>5.8565e-05</ixy>
            <ixz>-3.6623e-05</ixz>
            <iyy>7.9427e-05</iyy>
            <iyz>8.6784e-05</iyz>
            <izz>0.00016522</izz>
          </inertia>
        </inertial>
        <collision name='rotor_0_collision'>
          <pose relative_to='rotor_0_joint'>0 0 0 -0.28103 -0.463643 -0.523</pose>
          <geometry>
            <cylinder>
              <length>0.04</length>
              <radius>0.228</radius>
            </cylinder>
          </geometry>
          <max_contacts>10</max_contacts>
          <surface>
            <contact>
              <ode/>
            </contact>
            <bounce/>
            <friction>
              <torsional>
                <ode/>
              </torsional>
              <ode/>
            </friction>
          </surface>
        </collision>
        <gravity>1</gravity>
        <velocity_decay/>
        <self_collide>0</self_collide>
        <enable_wind>0</enable_wind>
        <kinematic>0</kinematic>
      </link>
      <joint name='rotor_1_joint' type='revolute'>
        <pose relative_to='base_link'>0.019547 0.52175 0.033856 0 -0 0</pose>
        <parent>base_link</parent>
        <child>rotor_1</child>
        <axis>
          <xyz>0.5 0 0.86603</xyz>
          <limit>
            <lower>-1e+16</lower>
            <upper>1e+16</upper>
            <effort>10</effort>
            <velocity>-1</velocity>
          </limit>
          <dynamics>
            <damping>0.005</damping>
            <spring_reference>0</spring_reference>
            <spring_stiffness>0</spring_stiffness>
          </dynamics>
          <use_parent_model_frame>1</use_parent_model_frame>
        </axis>
        <physics>
          <ode>
            <implicit_spring_damper>1</implicit_spring_damper>
            <limit>
              <cfm>0</cfm>
              <erp>0.2</erp>
            </limit>
          </ode>
        </physics>
      </joint>
      <link name='rotor_1'>
        <pose relative_to='rotor_1_joint'>0 0 0 0 -0 0</pose>
        <inertial>
          <pose>0.000229 0.001028 -0.000896 0 -0 0</pose>
          <mass>0.015914</mass>
          <inertia>
            <ixx>0.00010119</ixx>
            <ixy>8.4679e-05</ixy>
            <ixz>6.8123e-05</ixz>
            <iyy>0.00015735</iyy>
            <iyz>-4.8888e-05</iyz>
            <izz>0.00017985</izz>
          </inertia>
        </inertial>
        <collision name='rotor_1_collision'>
          <pose relative_to='rotor_1_joint'>0 0 0 0.523596 -0 1.5708</pose>
          <geometry>
            <cylinder>
              <length>0.04</length>
              <radius>0.228</radius>
            </cylinder>
          </geometry>
          <max_contacts>10</max_contacts>
          <surface>
            <contact>
              <ode/>
            </contact>
            <bounce/>
            <friction>
              <torsional>
                <ode/>
              </torsional>
              <ode/>
            </friction>
          </surface>
        </collision>
        <gravity>1</gravity>
        <velocity_decay/>
        <self_collide>0</self_collide>
        <enable_wind>0</enable_wind>
        <kinematic>0</kinematic>
      </link>
      <joint name='rotor_2_joint' type='revolute'>
        <pose relative_to='base_link'>-0.46162 0.24395 0.033856 0 -0 0</pose>
        <parent>base_link</parent>
        <child>rotor_2</child>
        <axis>
          <xyz>-0.25 -0.43301 0.86603</xyz>
          <limit>
            <lower>-1e+16</lower>
            <upper>1e+16</upper>
            <effort>10</effort>
            <velocity>-1</velocity>
          </limit>
          <dynamics>
            <damping>0.005</damping>
            <spring_reference>0</spring_reference>
            <spring_stiffness>0</spring_stiffness>
          </dynamics>
          <use_parent_model_frame>1</use_parent_model_frame>
        </axis>
        <physics>
          <ode>
            <implicit_spring_damper>1</implicit_spring_damper>
            <limit>
              <cfm>0</cfm>
              <erp>0.2</erp>
            </limit>
          </ode>
        </physics>
      </joint>
      <link name='rotor_2'>
        <pose relative_to='rotor_2_joint'>0 0 0 0 -0 0</pose>
        <inertial>
          <pose>0.000358 0.001336 7e-06 0 -0 0</pose>
          <mass>0.015914</mass>
          <inertia>
            <ixx>1.9696e-05</ixx>
            <ixy>5.2897e-05</ixy>
            <ixz>-3.1137e-05</ixz>
            <iyy>0.00020452</iyy>
            <iyz>7.945e-06</iyz>
            <izz>0.00021416</izz>
          </inertia>
        </inertial>
        <collision name='rotor_2_collision'>
          <pose relative_to='rotor_2_joint'>0 0 0 0.281033 -0.463643 0.523601</pose>
          <geometry>
            <cylinder>
              <length>0.04</length>
              <radius>0.228</radius>
            </cylinder>
          </geometry>
          <max_contacts>10</max_contacts>
          <surface>
            <contact>
              <ode/>
            </contact>
            <bounce/>
            <friction>
              <torsional>
                <ode/>
              </torsional>
              <ode/>
            </friction>
          </surface>
        </collision>
        <gravity>1</gravity>
        <velocity_decay/>
        <self_collide>0</self_collide>
        <enable_wind>0</enable_wind>
        <kinematic>0</kinematic>
      </link>
      <joint name='rotor_3_joint' type='revolute'>
        <pose relative_to='base_link'>-0.46162 -0.24395 0.033856 0 -0 0</pose>
        <parent>base_link</parent>
        <child>rotor_3</child>
        <axis>
          <xyz>-0.25 0.43301 0.86603</xyz>
          <limit>
            <lower>-1e+16</lower>
            <upper>1e+16</upper>
            <effort>10</effort>
            <velocity>-1</velocity>
          </limit>
          <dynamics>
            <damping>0.005</damping>
            <spring_reference>0</spring_reference>
            <spring_stiffness>0</spring_stiffness>
          </dynamics>
          <use_parent_model_frame>1</use_parent_model_frame>
        </axis>
        <physics>
          <ode>
            <implicit_spring_damper>1</implicit_spring_damper>
            <limit>
              <cfm>0</cfm>
              <erp>0.2</erp>
            </limit>
          </ode>
        </physics>
      </joint>
      <link name='rotor_3'>
        <pose relative_to='rotor_3_joint'>0 0 0 0 -0 0</pose>
        <inertial>
          <pose>-0.0007 -0.001122 -0.000405 0 -0 0</pose>
          <mass>0.015914</mass>
          <inertia>
            <ixx>0.00012438</ixx>
            <ixy>8.3004e-05</ixy>
            <ixz>-6.8869e-05</ixz>
            <iyy>0.00014518</iyy>
            <iyz>6.0956e-05</iyz>
            <izz>0.00016882</izz>
          </inertia>
        </inertial>
        <collision name='rotor_3_collision'>
          <pose relative_to='rotor_3_joint'>0 0 0 -0.28103 -0.463643 -0.523</pose>
          <geometry>
            <cylinder>
              <length>0.04</length>
              <radius>0.228</radius>
            </cylinder>
          </geometry>
          <max_contacts>10</max_contacts>
          <surface>
            <contact>
              <ode/>
            </contact>
            <bounce/>
            <friction>
              <torsional>
                <ode/>
              </torsional>
              <ode/>
            </friction>
          </surface>
        </collision>
        <gravity>1</gravity>
        <velocity_decay/>
        <self_collide>0</self_collide>
        <enable_wind>0</enable_wind>
        <kinematic>0</kinematic>
      </link>
      <joint name='rotor_4_joint' type='revolute'>
        <pose relative_to='base_link'>0.019547 -0.52175 0.033856 0 -0 0</pose>
        <parent>base_link</parent>
        <child>rotor_4</child>
        <axis>
          <xyz>0.5 0 0.86603</xyz>
          <limit>
            <lower>-1e+16</lower>
            <upper>1e+16</upper>
            <effort>10</effort>
            <velocity>-1</velocity>
          </limit>
          <dynamics>
            <damping>0.005</damping>
            <spring_reference>0</spring_reference>
            <spring_stiffness>0</spring_stiffness>
          </dynamics>
          <use_parent_model_frame>1</use_parent_model_frame>
        </axis>
        <physics>
          <ode>
            <implicit_spring_damper>1</implicit_spring_damper>
            <limit>
              <cfm>0</cfm>
              <erp>0.2</erp>
            </limit>
          </ode>
        </physics>
      </joint>
      <link name='rotor_4'>
        <pose relative_to='rotor_4_joint'>0 0 0 0 -0 0</pose>
        <inertial>
          <pose>0.000182 -0.00106 -0.00087 0 -0 0</pose>
          <mass>0.015914</mass>
          <inertia>
            <ixx>9.4764e-05</ixx>
            <ixy>-8.0636e-05</ixy>
            <ixz>7.1832e-05</ixz>
            <iyy>0.00016592</iyy>
            <iyz>4.6554e-05</iyz>
            <izz>0.00017771</izz>
          </inertia>
        </inertial>
        <collision name='rotor_4_collision'>
          <pose relative_to='rotor_4_joint'>0 0 0 0.523596 -0 1.5708</pose>
          <geometry>
            <cylinder>
              <length>0.04</length>
              <radius>0.228</radius>
            </cylinder>
          </geometry>
          <max_contacts>10</max_contacts>
          <surface>
            <contact>
              <ode/>
            </contact>
            <bounce/>
            <friction>
              <torsional>
                <ode/>
              </torsional>
              <ode/>
            </friction>
          </surface>
        </collision>
        <gravity>1</gravity>
        <velocity_decay/>
        <self_collide>0</self_collide>
        <enable_wind>0</enable_wind>
        <kinematic>0</kinematic>
      </link>
      <joint name='rotor_5_joint' type='revolute'>
        <pose relative_to='base_link'>0.44207 -0.2778 0.033856 0 -0 0</pose>
        <parent>base_link</parent>
        <child>rotor_5</child>
        <axis>
          <xyz>-0.25 -0.43301 0.86603</xyz>
          <limit>
            <lower>-1e+16</lower>
            <upper>1e+16</upper>
            <effort>10</effort>
            <velocity>-1</velocity>
          </limit>
          <dynamics>
            <damping>0.005</damping>
            <spring_reference>0</spring_reference>
            <spring_stiffness>0</spring_stiffness>
          </dynamics>
          <use_parent_model_frame>1</use_parent_model_frame>
        </axis>
        <physics>
          <ode>
            <implicit_spring_damper>1</implicit_spring_damper>
            <limit>
              <cfm>0</cfm>
              <erp>0.2</erp>
            </limit>
          </ode>
        </physics>
      </joint>
      <link name='rotor_5'>
        <pose relative_to='rotor_5_joint'>0 0 0 0 -0 0</pose>
        <inertial>
          <pose>-2.7e-05 -0.000763 -0.001153 0 -0 0</pose>
          <mass>0.015914</mass>
          <inertia>
            <ixx>1.9696e-05</ixx>
            <ixy>5.2897e-05</ixy>
            <ixz>-3.1137e-05</ixz>
            <iyy>0.00020453</iyy>
            <iyz>7.9429e-06</iyz>
            <izz>0.00021416</izz>
          </inertia>
        </inertial>
        <collision name='rotor_5_collision'>
          <pose relative_to='rotor_5_joint'>0 0 0 0.281033 -0.463643 0.523601</pose>
          <geometry>
            <cylinder>
              <length>0.04</length>
              <radius>0.228</radius>
            </cylinder>
          </geometry>
          <max_contacts>10</max_contacts>
          <surface>
            <contact>
              <ode/>
            </contact>
            <bounce/>
            <friction>
              <torsional>
                <ode/>
              </torsional>
              <ode/>
            </friction>
          </surface>
        </collision>
        <gravity>1</gravity>
        <velocity_decay/>
        <self_collide>0</self_collide>
        <enable_wind>0</enable_wind>
        <kinematic>0</kinematic>
      </link>
      <link name='skyvortex_zzx/imu_link'>
        <pose>0 0 0 0 -0 0</pose>
        <inertial>
          <pose>0 0 0 0 -0 0</pose>
          <mass>0.015</mass>
          <inertia>
            <ixx>1e-05</ixx>
            <ixy>0</ixy>
            <ixz>0</ixz>
            <iyy>1e-05</iyy>
            <iyz>0</iyz>
            <izz>1e-05</izz>
          </inertia>
        </inertial>
        <self_collide>0</self_collide>
        <enable_wind>0</enable_wind>
        <kinematic>0</kinematic>
      </link>
      <joint name='skyvortex_zzx/imu_joint' type='revolute'>
        <child>skyvortex_zzx/imu_link</child>
        <parent>base_link</parent>
        <axis>
          <xyz>1 0 0</xyz>
          <limit>
            <lower>0</lower>
            <upper>0</upper>
            <effort>0</effort>
            <velocity>0</velocity>
          </limit>
          <dynamics>
            <spring_reference>0</spring_reference>
            <spring_stiffness>0</spring_stiffness>
          </dynamics>
          <use_parent_model_frame>1</use_parent_model_frame>
        </axis>
      </joint>
      <frame name='gps::__model__' attached_to='gps::link'>
        <pose relative_to='__model__'>0 0 0 0 -0 0</pose>
      </frame>
      <link name='gps::link'>
        <pose relative_to='gps::__model__'>0 0 0 0 -0 0</pose>
        <inertial>
          <pose>0 0 0 0 -0 0</pose>
          <mass>0.015</mass>
          <inertia>
            <ixx>1e-05</ixx>
            <ixy>0</ixy>
            <ixz>0</ixz>
            <iyy>1e-05</iyy>
            <iyz>0</iyz>
            <izz>1e-05</izz>
          </inertia>
        </inertial>
        <visual name='visual'>
          <geometry>
            <cylinder>
              <radius>0.01</radius>
              <length>0.002</length>
            </cylinder>
          </geometry>
          <material>
            <script>
              <name>Gazebo/Black</name>
              <uri>__default__</uri>
            </script>
          </material>
        </visual>
        <sensor name='gps' type='gps'>
          <pose>0 0 0 0 -0 0</pose>
          <update_rate>5</update_rate>
          <always_on>1</always_on>
          <visualize>0</visualize>
          <plugin name='gps_plugin' filename='libgazebo_gps_plugin.so'>
            <robotNamespace/>
            <gpsNoise>1</gpsNoise>
            <gpsXYRandomWalk>2.0</gpsXYRandomWalk>
            <gpsZRandomWalk>4.0</gpsZRandomWalk>
            <gpsXYNoiseDensity>2.0e-4</gpsXYNoiseDensity>
            <gpsZNoiseDensity>4.0e-4</gpsZNoiseDensity>
            <gpsVXYNoiseDensity>0.2</gpsVXYNoiseDensity>
            <gpsVZNoiseDensity>0.4</gpsVZNoiseDensity>
          </plugin>
          <gps/>
        </sensor>
        <self_collide>0</self_collide>
        <enable_wind>0</enable_wind>
        <kinematic>0</kinematic>
      </link>
      <joint name='gps_joint' type='fixed'>
        <child>gps::link</child>
        <parent>base_link</parent>
      </joint>
      <joint name='d435i_camera_joint' type='fixed'>
        <pose relative_to='operator_1_Link'>-0.1084 0.001842 0.21154 0 -0.5236 -0.016991</pose>
        <child>d435i_camera::base_link</child>
        <parent>operator_1_Link</parent>
      </joint>
      <frame name='d435i_camera::__model__' attached_to='d435i_camera::base_link'>
        <pose relative_to='d435i_camera_joint'>0 0 0 0 -0 0</pose>
      </frame>
      <link name='d435i_camera::base_link'>
        <pose relative_to='d435i_camera::__model__'>0 0 0 0 -0 0</pose>
        <inertial>
          <pose>0.0106 0.0175 0.0125 0 -0 0</pose>
          <mass>0.072</mass>
          <inertia>
            <ixx>0.00388124</ixx>
            <ixy>-1.69407e-21</ixy>
            <ixz>0</ixz>
            <iyy>0.00049894</iyy>
            <iyz>0</iyz>
            <izz>0.00387926</izz>
          </inertia>
        </inertial>
        <collision name='base_link_collision'>
          <pose>0.0106 0 0.0125 0 -0 0</pose>
          <geometry>
            <box>
              <size>0.02505 0.09 0.025</size>
            </box>
          </geometry>
          <surface>
            <contact>
              <ode>
                <kp>1e+13</kp>
                <kd>1</kd>
              </ode>
            </contact>
            <friction>
              <ode>
                <mu2>1</mu2>
                <fdir1>0 0 0</fdir1>
              </ode>
              <torsional>
                <ode/>
              </torsional>
            </friction>
            <bounce/>
          </surface>
          <max_contacts>10</max_contacts>
        </collision>
        <visual name='base_link_visual'>
          <pose>0.0149 0 0.0125 1.5708 -0 1.5708</pose>
          <geometry>
            <mesh>
              <scale>1 1 1</scale>
              <uri>meshes/d435.dae</uri>
            </mesh>
          </geometry>
          <material>
            <script>
              <uri>__default__</uri>
              <name>__default__</name>
            </script>
          </material>
        </visual>
        <gravity>1</gravity>
        <velocity_decay/>
        <self_collide>0</self_collide>
        <enable_wind>0</enable_wind>
        <kinematic>0</kinematic>
        <gravity>1</gravity>
        <sensor name='cameracolor' type='camera'>
          <camera name='camera'>
            <horizontal_fov>1.21126</horizontal_fov>
            <image>
              <width>640</width>
              <height>480</height>
              <format>RGB_INT8</format>
            </image>
            <clip>
              <near>0.1</near>
              <far>100</far>
            </clip>
            <noise>
              <type>gaussian</type>
              <mean>0</mean>
              <stddev>0.007</stddev>
            </noise>
          </camera>
          <always_on>1</always_on>
          <update_rate>30</update_rate>
          <visualize>0</visualize>
          <pose>0.0106 0.0175 0.0125 0 -0 0</pose>
        </sensor>
        <sensor name='cameraired1' type='camera'>
          <camera name='camera'>
            <horizontal_fov>1.48702</horizontal_fov>
            <image>
              <width>1280</width>
              <height>720</height>
              <format>L_INT8</format>
            </image>
            <clip>
              <near>0.1</near>
              <far>100</far>
            </clip>
            <noise>
              <type>gaussian</type>
              <mean>0</mean>
              <stddev>0.05</stddev>
            </noise>
          </camera>
          <always_on>1</always_on>
          <update_rate>90</update_rate>
          <visualize>0</visualize>
          <pose>0.0106 0.0175 0.0125 0 -0 0</pose>
        </sensor>
        <sensor name='cameraired2' type='camera'>
          <camera name='camera'>
            <horizontal_fov>1.48702</horizontal_fov>
            <image>
              <width>1280</width>
              <height>720</height>
              <format>L_INT8</format>
            </image>
            <clip>
              <near>0.1</near>
              <far>100</far>
            </clip>
            <noise>
              <type>gaussian</type>
              <mean>0</mean>
              <stddev>0.05</stddev>
            </noise>
          </camera>
          <always_on>1</always_on>
          <update_rate>90</update_rate>
          <visualize>0</visualize>
          <pose>0.0106 0.0175 0.0125 0 -0 0</pose>
        </sensor>
        <sensor name='cameradepth' type='depth'>
          <camera name='camera'>
            <horizontal_fov>1.48702</horizontal_fov>
            <image>
              <width>1280</width>
              <height>720</height>
            </image>
            <clip>
              <near>0.1</near>
              <far>100</far>
            </clip>
            <noise>
              <type>gaussian</type>
              <mean>0</mean>
              <stddev>0.1</stddev>
            </noise>
          </camera>
          <always_on>1</always_on>
          <update_rate>90</update_rate>
          <visualize>0</visualize>
          <pose>0.0106 0.0175 0.0125 0 -0 0</pose>
        </sensor>
      </link>
      <static>0</static>
      <plugin name='camera' filename='librealsense_gazebo_plugin.so'>
        <prefix>camera</prefix>
        <depthUpdateRate>30.0</depthUpdateRate>
        <colorUpdateRate>30.0</colorUpdateRate>
        <infraredUpdateRate>30.0</infraredUpdateRate>
        <depthTopicName>depth/image_raw</depthTopicName>
        <depthCameraInfoTopicName>depth/camera_info</depthCameraInfoTopicName>
        <colorTopicName>color/image_raw</colorTopicName>
        <colorCameraInfoTopicName>color/camera_info</colorCameraInfoTopicName>
        <infrared1TopicName>infra1/image_raw</infrared1TopicName>
        <infrared1CameraInfoTopicName>infra1/camera_info</infrared1CameraInfoTopicName>
        <infrared2TopicName>infra2/image_raw</infrared2TopicName>
        <infrared2CameraInfoTopicName>infra2/camera_info</infrared2CameraInfoTopicName>
        <colorOpticalframeName>color_optical_frame</colorOpticalframeName>
        <depthOpticalframeName>depth_optical_frame</depthOpticalframeName>
        <infrared1OpticalframeName>camera_left_ir_optical_frame</infrared1OpticalframeName>
        <infrared2OpticalframeName>camera_right_ir_optical_frame</infrared2OpticalframeName>
        <rangeMinDepth>0.2</rangeMinDepth>
        <rangeMaxDepth>10.0</rangeMaxDepth>
        <pointCloud>1</pointCloud>
        <pointCloudTopicName>depth/color/points</pointCloudTopicName>
        <pointCloudCutoff>0.25</pointCloudCutoff>
        <pointCloudCutoffMax>3.0</pointCloudCutoffMax>
      </plugin>
      <plugin name='rosbag' filename='libgazebo_multirotor_base_plugin.so'>
        <robotNamespace/>
        <linkName>base_link</linkName>
        <rotorVelocitySlowdownSim>10</rotorVelocitySlowdownSim>
      </plugin>
      <plugin name='front_left_motor_model' filename='libgazebo_motor_model.so'>
        <robotNamespace/>
        <jointName>rotor_0_joint</jointName>
        <linkName>rotor_0</linkName>
        <turningDirection>cw</turningDirection>
        <timeConstantUp>0.0125</timeConstantUp>
        <timeConstantDown>0.025</timeConstantDown>
        <maxRotVelocity>1500</maxRotVelocity>
        <motorConstant>9.74858e-06</motorConstant>
        <momentConstant>0.06</momentConstant>
        <commandSubTopic>/gazebo/command/motor_speed</commandSubTopic>
        <motorNumber>2</motorNumber>
        <rotorDragCoefficient>0.000806428</rotorDragCoefficient>
        <rollingMomentCoefficient>1e-06</rollingMomentCoefficient>
        <motorSpeedPubTopic>/motor_speed/2</motorSpeedPubTopic>
        <rotorVelocitySlowdownSim>10</rotorVelocitySlowdownSim>
      </plugin>
      <plugin name='medial_left_motor_model' filename='libgazebo_motor_model.so'>
        <robotNamespace/>
        <jointName>rotor_1_joint</jointName>
        <linkName>rotor_1</linkName>
        <turningDirection>ccw</turningDirection>
        <timeConstantUp>0.0125</timeConstantUp>
        <timeConstantDown>0.025</timeConstantDown>
        <maxRotVelocity>1500</maxRotVelocity>
        <motorConstant>9.74858e-06</motorConstant>
        <momentConstant>0.06</momentConstant>
        <commandSubTopic>/gazebo/command/motor_speed</commandSubTopic>
        <motorNumber>1</motorNumber>
        <rotorDragCoefficient>0.000806428</rotorDragCoefficient>
        <rollingMomentCoefficient>1e-06</rollingMomentCoefficient>
        <motorSpeedPubTopic>/motor_speed/1</motorSpeedPubTopic>
        <rotorVelocitySlowdownSim>10</rotorVelocitySlowdownSim>
      </plugin>
      <plugin name='back_left_motor_model' filename='libgazebo_motor_model.so'>
        <robotNamespace/>
        <jointName>rotor_2_joint</jointName>
        <linkName>rotor_2</linkName>
        <turningDirection>cw</turningDirection>
        <timeConstantUp>0.0125</timeConstantUp>
        <timeConstantDown>0.025</timeConstantDown>
        <maxRotVelocity>1500</maxRotVelocity>
        <motorConstant>9.74858e-06</motorConstant>
        <momentConstant>0.06</momentConstant>
        <commandSubTopic>/gazebo/command/motor_speed</commandSubTopic>
        <motorNumber>5</motorNumber>
        <rotorDragCoefficient>0.000806428</rotorDragCoefficient>
        <rollingMomentCoefficient>1e-06</rollingMomentCoefficient>
        <motorSpeedPubTopic>/motor_speed/5</motorSpeedPubTopic>
        <rotorVelocitySlowdownSim>10</rotorVelocitySlowdownSim>
      </plugin>
      <plugin name='back_right_motor_model' filename='libgazebo_motor_model.so'>
        <robotNamespace/>
        <jointName>rotor_3_joint</jointName>
        <linkName>rotor_3</linkName>
        <turningDirection>ccw</turningDirection>
        <timeConstantUp>0.0125</timeConstantUp>
        <timeConstantDown>0.025</timeConstantDown>
        <maxRotVelocity>1500</maxRotVelocity>
        <motorConstant>9.74858e-06</motorConstant>
        <momentConstant>0.06</momentConstant>
        <commandSubTopic>/gazebo/command/motor_speed</commandSubTopic>
        <motorNumber>3</motorNumber>
        <rotorDragCoefficient>0.000806428</rotorDragCoefficient>
        <rollingMomentCoefficient>1e-06</rollingMomentCoefficient>
        <motorSpeedPubTopic>/motor_speed/3</motorSpeedPubTopic>
        <rotorVelocitySlowdownSim>10</rotorVelocitySlowdownSim>
      </plugin>
      <plugin name='medial_right_motor_model' filename='libgazebo_motor_model.so'>
        <robotNamespace/>
        <jointName>rotor_4_joint</jointName>
        <linkName>rotor_4</linkName>
        <turningDirection>cw</turningDirection>
        <timeConstantUp>0.0125</timeConstantUp>
        <timeConstantDown>0.025</timeConstantDown>
        <maxRotVelocity>1500</maxRotVelocity>
        <motorConstant>9.74858e-06</motorConstant>
        <momentConstant>0.06</momentConstant>
        <commandSubTopic>/gazebo/command/motor_speed</commandSubTopic>
        <motorNumber>0</motorNumber>
        <rotorDragCoefficient>0.000806428</rotorDragCoefficient>
        <rollingMomentCoefficient>1e-06</rollingMomentCoefficient>
        <motorSpeedPubTopic>/motor_speed/0</motorSpeedPubTopic>
        <rotorVelocitySlowdownSim>10</rotorVelocitySlowdownSim>
      </plugin>
      <plugin name='front_right_motor_model' filename='libgazebo_motor_model.so'>
        <robotNamespace/>
        <jointName>rotor_5_joint</jointName>
        <linkName>rotor_5</linkName>
        <turningDirection>ccw</turningDirection>
        <timeConstantUp>0.0125</timeConstantUp>
        <timeConstantDown>0.025</timeConstantDown>
        <maxRotVelocity>1500</maxRotVelocity>
        <motorConstant>9.74858e-06</motorConstant>
        <momentConstant>0.06</momentConstant>
        <commandSubTopic>/gazebo/command/motor_speed</commandSubTopic>
        <motorNumber>4</motorNumber>
        <rotorDragCoefficient>0.000806428</rotorDragCoefficient>
        <rollingMomentCoefficient>1e-06</rollingMomentCoefficient>
        <motorSpeedPubTopic>/motor_speed/4</motorSpeedPubTopic>
        <rotorVelocitySlowdownSim>10</rotorVelocitySlowdownSim>
      </plugin>
      <plugin name='groundtruth_plugin' filename='libgazebo_groundtruth_plugin.so'>
        <robotNamespace/>
      </plugin>
      <plugin name='magnetometer_plugin' filename='libgazebo_magnetometer_plugin.so'>
        <robotNamespace/>
        <pubRate>100</pubRate>
        <noiseDensity>0.0004</noiseDensity>
        <randomWalk>6.4e-06</randomWalk>
        <biasCorrelationTime>600</biasCorrelationTime>
        <magTopic>/mag</magTopic>
      </plugin>
      <plugin name='barometer_plugin' filename='libgazebo_barometer_plugin.so'>
        <robotNamespace/>
        <pubRate>50</pubRate>
        <baroTopic>/baro</baroTopic>
      </plugin>
      <plugin name='mavlink_interface' filename='libgazebo_mavlink_interface.so'>
        <robotNamespace/>
        <imuSubTopic>/imu</imuSubTopic>
        <magSubTopic>/mag</magSubTopic>
        <baroSubTopic>/baro</baroSubTopic>
        <mavlink_addr>INADDR_ANY</mavlink_addr>
        <mavlink_udp_port>14560</mavlink_udp_port>
        <serialEnabled>0</serialEnabled>
        <serialDevice>/dev/ttyACM0</serialDevice>
        <baudRate>921600</baudRate>
        <qgc_addr>INADDR_ANY</qgc_addr>
        <qgc_udp_port>14550</qgc_udp_port>
        <sdk_addr>INADDR_ANY</sdk_addr>
        <sdk_udp_port>14540</sdk_udp_port>
        <hil_mode>0</hil_mode>
        <hil_state_level>0</hil_state_level>
        <enable_lockstep>0</enable_lockstep>
        <use_tcp>1</use_tcp>
        <motorSpeedCommandPubTopic>/gazebo/command/motor_speed</motorSpeedCommandPubTopic>
        <control_channels>
          <channel name='rotor0'>
            <input_index>0</input_index>
            <input_offset>0</input_offset>
            <input_scaling>1500</input_scaling>
            <zero_position_disarmed>0</zero_position_disarmed>
            <zero_position_armed>100</zero_position_armed>
            <joint_control_type>velocity</joint_control_type>
            <joint_name>rotor_4_joint</joint_name>
          </channel>
          <channel name='rotor1'>
            <input_index>1</input_index>
            <input_offset>0</input_offset>
            <input_scaling>1500</input_scaling>
            <zero_position_disarmed>0</zero_position_disarmed>
            <zero_position_armed>100</zero_position_armed>
            <joint_control_type>velocity</joint_control_type>
            <joint_name>rotor_1_joint</joint_name>
          </channel>
          <channel name='rotor2'>
            <input_index>2</input_index>
            <input_offset>0</input_offset>
            <input_scaling>1500</input_scaling>
            <zero_position_disarmed>0</zero_position_disarmed>
            <zero_position_armed>100</zero_position_armed>
            <joint_control_type>velocity</joint_control_type>
            <joint_name>rotor_0_joint</joint_name>
          </channel>
          <channel name='rotor3'>
            <input_index>3</input_index>
            <input_offset>0</input_offset>
            <input_scaling>1500</input_scaling>
            <zero_position_disarmed>0</zero_position_disarmed>
            <zero_position_armed>100</zero_position_armed>
            <joint_control_type>velocity</joint_control_type>
            <joint_name>rotor_3_joint</joint_name>
          </channel>
          <channel name='rotor4'>
            <input_index>4</input_index>
            <input_offset>0</input_offset>
            <input_scaling>1500</input_scaling>
            <zero_position_disarmed>0</zero_position_disarmed>
            <zero_position_armed>100</zero_position_armed>
            <joint_control_type>velocity</joint_control_type>
            <joint_name>rotor_5_joint</joint_name>
          </channel>
          <channel name='rotor5'>
            <input_index>5</input_index>
            <input_offset>0</input_offset>
            <input_scaling>1500</input_scaling>
            <zero_position_disarmed>0</zero_position_disarmed>
            <zero_position_armed>100</zero_position_armed>
            <joint_control_type>velocity</joint_control_type>
            <joint_name>rotor_2_joint</joint_name>
          </channel>
        </control_channels>
      </plugin>
      <static>0</static>
      <plugin name='gazebo_imu_plugin' filename='libgazebo_imu_plugin.so'>
        <robotNamespace/>
        <linkName>skyvortex_zzx/imu_link</linkName>
        <imuTopic>/imu</imuTopic>
        <gyroscopeNoiseDensity>0.0000394</gyroscopeNoiseDensity>
        <gyroscopeRandomWalk>3.8785e-05</gyroscopeRandomWalk>
        <gyroscopeBiasCorrelationTime>1000.0</gyroscopeBiasCorrelationTime>
        <gyroscopeTurnOnBiasSigma>0.0087</gyroscopeTurnOnBiasSigma>
        <accelerometerNoiseDensity>0.000</accelerometerNoiseDensity>
        <accelerometerRandomWalk>0.006</accelerometerRandomWalk>
        <accelerometerBiasCorrelationTime>300.0</accelerometerBiasCorrelationTime>
        <accelerometerTurnOnBiasSigma>0.196</accelerometerTurnOnBiasSigma>
      </plugin>
      <plugin name='position_controller' filename='libposition_controller.so'>
        <joint_name>operator_1_joint</joint_name>
        <p_gain>1</p_gain>
        <i_gain>0.1</i_gain>
        <d_gain>0.1</d_gain>
        <robotNamespace>/</robotNamespace>
      </plugin>
      <plugin name='joint_state_publisher' filename='libgazebo_ros_joint_state_publisher.so'>
        <robotNamespace>/</robotNamespace>
        <jointName>operator_1_joint, rotor_0_joint, rotor_1_joint, rotor_2_joint, rotor_3_joint, rotor_4_joint, rotor_5_joint, connect_joint, wheel1_joint, wheel2_joint, wheel3_joint</jointName>
        <updateRate>50.0</updateRate>
      </plugin>
      <pose>0 0 0.2 0 -0 0</pose>
    </model>
    <model name='wall'>
      <pose>0.864001 0.10692 0 0 -0 0</pose>
      <link name='Wall_4'>
        <collision name='Wall_4_Collision'>
          <geometry>
            <box>
              <size>4 0.15 2.5</size>
            </box>
          </geometry>
          <pose>0 0 1.25 0 -0 0</pose>
          <max_contacts>10</max_contacts>
          <surface>
            <contact>
              <ode/>
            </contact>
            <bounce/>
            <friction>
              <torsional>
                <ode/>
              </torsional>
              <ode/>
            </friction>
          </surface>
        </collision>
        <visual name='Wall_4_Visual'>
          <pose>0 0 1.25 0 -0 0</pose>
          <geometry>
            <box>
              <size>4 0.15 2.5</size>
            </box>
          </geometry>
          <material>
            <script>
              <uri>file://media/materials/scripts/gazebo.material</uri>
              <name>Gazebo/Grey</name>
            </script>
            <ambient>1 1 1 1</ambient>
          </material>
          <meta>
            <layer>0</layer>
          </meta>
        </visual>
        <pose>0.789001 -0 0 0 -0 -1.5708</pose>
        <self_collide>0</self_collide>
        <enable_wind>0</enable_wind>
        <kinematic>0</kinematic>
      </link>
      <static>1</static>
    </model>
    <state world_name='default'>
      <sim_time>129 88000000</sim_time>
      <real_time>130 176398421</real_time>
      <wall_time>1732957993 15218895</wall_time>
      <iterations>32272</iterations>
      <model name='asphalt_plane'>
        <pose>0 0 0 0 -0 0</pose>
        <scale>1 1 1</scale>
        <link name='link'>
          <pose>0 0 0 0 -0 0</pose>
          <velocity>0 0 0 0 -0 0</velocity>
          <acceleration>0 0 0 0 -0 0</acceleration>
          <wrench>0 0 0 0 -0 0</wrench>
        </link>
      </model>
      <model name='ground_plane'>
        <pose>0 0 0 0 -0 0</pose>
        <scale>1 1 1</scale>
        <link name='link'>
          <pose>0 0 0 0 -0 0</pose>
          <velocity>0 0 0 0 -0 0</velocity>
          <acceleration>0 0 0 0 -0 0</acceleration>
          <wrench>0 0 0 0 -0 0</wrench>
        </link>
      </model>
      <model name='skyvortex'>
        <pose>-0.000704 0.000584 0.397094 -0.001425 -0.001719 -0.000112</pose>
        <scale>1 1 1</scale>
        <link name='base_link'>
          <pose>-0.000704 0.000584 0.397094 -0.001425 -0.001719 -0.000112</pose>
          <velocity>-1.1e-05 3.7e-05 1.8e-05 -0.000107 -3.1e-05 0</velocity>
          <acceleration>-0.012387 -0.005937 -0.004892 0.01688 -0.035213 -0.000224</acceleration>
          <wrench>-0.050884 -0.024388 -0.020093 0 -0 0</wrench>
        </link>
        <link name='connect_Link'>
          <pose>0.493337 -0.007178 0.758068 2.16403 -0.001395 -1.5879</pose>
          <velocity>2e-06 0.000401 0.000118 -0.000432 3e-06 2e-06</velocity>
          <acceleration>-0.012522 0.126529 0.017477 -0.572455 0.005993 -0.311514</acceleration>
          <wrench>-6e-06 5.7e-05 8e-06 0 -0 0</wrench>
        </link>
        <link name='d435i_camera::base_link'>
          <pose>-0.122737 0.003181 0.628972 -0.001681 -0.593233 -0.016166</pose>
          <velocity>1.5e-05 0.000284 9.8e-05 -0.000323 5e-06 -3e-06</velocity>
          <acceleration>-0.010408 0.076382 0.01097 -0.018234 -0.001848 0.00118</acceleration>
          <wrench>-0.000749 0.0055 0.00079 0 -0 0</wrench>
        </link>
        <link name='force_sensor'>
          <pose>0.796573 -0.01094 0.962896 -0.00463 0.980395 -0.004002</pose>
          <velocity>3.5e-05 -0.00018 -3.7e-05 -0.00032 5e-06 -3e-06</velocity>
          <acceleration>0.002185 0.009973 0.011383 -0.017693 0.000406 0.001173</acceleration>
          <wrench>2e-06 1e-05 1.1e-05 0 -0 0</wrench>
        </link>
        <link name='gps::link'>
          <pose>-0.000704 0.000584 0.397094 -0.001425 -0.00172 -0.000113</pose>
          <velocity>-1.1e-05 4.1e-05 1.9e-05 -0.0003 -3.4e-05 0</velocity>
          <acceleration>-0.012734 -0.005751 -0.004936 -0.013104 -0.035183 0.000981</acceleration>
          <wrench>-0.000191 -8.6e-05 -7.4e-05 0 -0 0</wrench>
        </link>
        <link name='operator_1_Link'>
          <pose>0.000118 0.000796 0.42555 -0.002584 -0.0696 2.3e-05</pose>
          <velocity>-1.2e-05 4.5e-05 1.9e-05 -0.0003 5e-06 0</velocity>
          <acceleration>-0.013743 -0.006643 -0.004848 -0.012497 0.000322 0.000931</acceleration>
          <wrench>-0.000137 -6.6e-05 -4.8e-05 0 -0 0</wrench>
        </link>
        <link name='rotor_0'>
          <pose>0.441339 0.278382 0.431314 -0.046133 0.094542 0.181259</pose>
          <velocity>-1.3e-05 5.1e-05 -5e-05 -0.000705 0.000844 0.001296</velocity>
          <acceleration>-0.013863 -0.003531 0.002127 -0.813837 1.08236 -0.32534</acceleration>
          <wrench>-0.000221 -5.6e-05 3.4e-05 0 -0 0</wrench>
        </link>
        <link name='rotor_1'>
          <pose>0.018845 0.522379 0.43024 -0.085329 -0.008241 -0.146282</pose>
          <velocity>-1.2e-05 5.1e-05 -0.000138 -0.000858 0.000155 -0.000968</velocity>
          <acceleration>-0.013365 -0.004165 -0.020741 -0.140975 -0.012953 -0.259147</acceleration>
          <wrench>-0.000213 -6.6e-05 -0.00033 0 -0 0</wrench>
        </link>
        <link name='rotor_2'>
          <pose>-0.462354 0.244634 0.429808 -0.019987 -0.031461 0.060978</pose>
          <velocity>-1.3e-05 5.1e-05 -7.1e-05 -0.000423 -0.000267 0.000405</velocity>
          <acceleration>-0.01371 -0.003908 -0.029053 -0.805236 0.053015 -0.041195</acceleration>
          <wrench>-0.000218 -6.2e-05 -0.000462 0 -0 0</wrench>
        </link>
        <link name='rotor_3'>
          <pose>-0.46241 -0.243266 0.430503 0.059402 -0.087355 -0.184407</pose>
          <velocity>-1.3e-05 5.1e-05 7.7e-05 9.1e-05 -0.000551 -0.001431</velocity>
          <acceleration>-0.013827 -0.003618 -0.013556 0.437338 -0.687047 0.012052</acceleration>
          <wrench>-0.00022 -5.8e-05 -0.000216 0 -0 0</wrench>
        </link>
        <link name='rotor_4'>
          <pose>0.018725 -0.521119 0.431726 0.085032 -0.008201 0.15049</pose>
          <velocity>-1.2e-05 5.1e-05 0.000177 0.000341 4.5e-05 0.001118</velocity>
          <acceleration>-0.013288 -0.003676 0.012548 0.165708 0.011556 0.25823</acceleration>
          <wrench>-0.000211 -5.8e-05 0.0002 0 -0 0</wrench>
        </link>
        <link name='rotor_5'>
          <pose>0.441275 -0.277217 0.432105 0.012359 0.023363 -0.049563</pose>
          <velocity>-1.3e-05 5.1e-05 0.000117 -0.000181 0.000163 -0.000414</velocity>
          <acceleration>-0.013709 -0.003791 0.020029 0.511403 -0.150024 -0.035965</acceleration>
          <wrench>-0.000218 -6e-05 0.000319 0 -0 0</wrench>
        </link>
        <link name='skyvortex_zzx/imu_link'>
          <pose>-0.000704 0.000584 0.397094 -0.001425 -0.00172 -0.000113</pose>
          <velocity>-1.1e-05 4e-05 1.9e-05 -0.000323 -3.4e-05 0</velocity>
          <acceleration>-0.012721 -0.00572 -0.004921 -0.012902 -0.035182 0.000981</acceleration>
          <wrench>-0.000191 -8.6e-05 -7.4e-05 0 -0 0</wrench>
        </link>
        <link name='wheel1_Link'>
          <pose>0.777168 -0.011624 1.05256 2.1623 -0.048329 -1.51818</pose>
          <velocity>3e-06 0.000528 0.000119 0.008341 -0.000165 -0.013011</velocity>
          <acceleration>-0.012509 0.133709 0.017452 -0.044205 -0.000401 -0.028305</acceleration>
          <wrench>-5e-06 5.5e-05 7e-06 0 -0 0</wrench>
        </link>
        <link name='wheel2_Link'>
          <pose>0.847572 -0.087018 0.946361 -2.71531 0.024539 0.306052</pose>
          <velocity>3e-06 0.000454 0.00014 -0.01489 0.047618 0.022596</velocity>
          <acceleration>-0.012117 0.111992 0.019407 -0.058994 -0.024723 -0.001324</acceleration>
          <wrench>-5e-06 4.6e-05 8e-06 0 -0 0</wrench>
        </link>
        <link name='wheel3_Link'>
          <pose>0.850105 0.061021 0.946162 -2.51678 -0.780164 2.34261</pose>
          <velocity>1e-06 0.000428 6.5e-05 0.003259 0.010779 -0.005202</velocity>
          <acceleration>-0.012722 0.099143 0.007353 -0.058555 0.025258 -0.001884</acceleration>
          <wrench>-5e-06 4.1e-05 3e-06 0 -0 0</wrench>
        </link>
      </model>
      <model name='wall'>
        <pose>0.864001 0.10692 0 0 -0 0</pose>
        <scale>1 1 1</scale>
        <link name='Wall_4'>
          <pose>1.653 0.10692 0 0 0 -1.5708</pose>
          <velocity>0 0 0 0 -0 0</velocity>
          <acceleration>0 0 0 0 -0 0</acceleration>
          <wrench>0 0 0 0 -0 0</wrench>
        </link>
      </model>
      <light name='sun'>
        <pose>0 0 10 0 -0 0</pose>
      </light>
      <light name='user_point_light_0'>
        <pose>-0.191859 0.550154 7.02258 0 -0 0</pose>
      </light>
    </state>
    <gui fullscreen='0'>
      <camera name='user_camera'>
        <pose>-2.92525 7.91356 3.18489 0 0.383643 -1.11581</pose>
        <view_controller>orbit</view_controller>
        <projection_type>perspective</projection_type>
      </camera>
    </gui>
  </world>
</sdf>
